<?xml version="1.0" ?>


<!-- =================================================================================== -->
<!-- |    This document was autogenerated by xacro from panda_arm.urdf.xacro           | -->
<!-- |    EDITING THIS FILE BY HAND IS NOT RECOMMENDED                                 | -->
<!-- =================================================================================== -->
<robot name="table" xmlns:xacro="http://www.ros.org/wiki/xacro">
  <link name="table_base">
    <!-- Bottom -->
    <visual>
        <origin rpy="0 0 0" xyz="0. 0. 0."/>
        <geometry>
            <box size="0.6 1.8 0.02"/>
        </geometry>
        <material name="panda white"/>
    </visual>

    <!-- Top -->
    <visual>
        <origin rpy="0 0 0" xyz="0. 0. 0.8"/>
        <geometry>
            <box size="0.6 1.8 0.02"/>
        </geometry>
        <material name="panda white"/>
    </visual>

    <!-- Back -->
    <visual>
        <origin rpy="0 0 0" xyz="-0.3 0. 0.4"/>
        <geometry>
            <box size="0.02 1.8 0.8"/>
        </geometry>
        <material name="panda white"/>
    </visual>

    <!-- Right -->
    <visual>
        <origin rpy="0 0 0" xyz="-0. 0.9 0.4"/>
        <geometry>
            <box size="0.6 0.02 0.8"/>
        </geometry>
        <material name="panda white"/>
    </visual>

    <!-- Left -->
    <visual>
        <origin rpy="0 0 0" xyz="-0. -0.9 0.4"/>
        <geometry>
            <box size="0.6 0.02 0.8"/>
        </geometry>
        <material name="panda white"/>
    </visual>

    <!-- Bottom -->
    <collision>
        <origin rpy="0 0 0" xyz="0. 0. 0."/>
        <geometry>
            <box size="0.6 1.8 0.02"/>
        </geometry>
        <material name="panda white"/>
    </collision>

    <!-- Top -->
    <collision>
        <origin rpy="0 0 0" xyz="0. 0. 0.8"/>
        <geometry>
            <box size="0.6 1.8 0.02"/>
        </geometry>
        <material name="panda white"/>
    </collision>

    <!-- Back -->
    <collision>
        <origin rpy="0 0 0" xyz="-0.3 0. 0.4"/>
        <geometry>
            <box size="0.02 1.8 0.8"/>
        </geometry>
        <material name="panda white"/>
    </collision>

    <!-- Right -->
    <collision>
        <origin rpy="0 0 0" xyz="-0. 0.9 0.4"/>
        <geometry>
            <box size="0.6 0.02 0.8"/>
        </geometry>
        <material name="panda white"/>
    </collision>

    <!-- Left -->
    <collision>
        <origin rpy="0 0 0" xyz="-0. -0.9 0.4"/>
        <geometry>
            <box size="0.6 0.02 0.8"/>
        </geometry>
        <material name="panda white"/>
    </collision>

  </link>

  <link name="door1">
    <visual>
        <origin rpy="0 0 0" xyz="0. 0.2 0."/>
        <geometry>
            <box size="0.02 0.4 0.8"/>
        </geometry>
        <material name="red"/>
    </visual>

    <collision>
        <origin rpy="0 0 0" xyz="0. 0.2 0."/>
        <geometry>
            <box size="0.02 0.4 0.8"/>
        </geometry>
        <material name="red"/>
    </collision>
  </link>

   <link name="door2">
    <visual>
        <origin rpy="0 0 0" xyz="0. -0.2 0."/>
        <geometry>
            <box size="0.02 0.4 0.8"/>
        </geometry>
        <material name="green"/>
    </visual>

    <collision>
        <origin rpy="0 0 0" xyz="0. -0.2 0."/>
        <geometry>
            <box size="0.02 0.4 0.8"/>
        </geometry>
        <material name="panda white"/>
    </collision>
  </link>

   <link name="door3">
    <visual>
        <origin rpy="0 0 0" xyz="0. 0.2 0."/>
        <geometry>
            <box size="0.02 0.4 0.8"/>
        </geometry>
        <material name="red"/>
    </visual>

    <collision>
        <origin rpy="0 0 0" xyz="0. 0.2 0."/>
        <geometry>
            <box size="0.02 0.4 0.8"/>
        </geometry>
        <material name="panda white"/>
    </collision>
  </link>

  <link name="door4">
    <visual>
        <origin rpy="0 0 0" xyz="0. 0.1 0."/>
        <geometry>
            <box size="0.02 0.2 0.8"/>
        </geometry>
        <material name="red"/>
    </visual>

    <collision>
        <origin rpy="0 0 0" xyz="0. 0.1 0."/>
        <geometry>
            <box size="0.02 0.2 0.8"/>
        </geometry>
        <material name="panda white"/>
    </collision>
  </link>

  <link name="drawer1">
  <!-- Bottom-->
    <visual>
        <origin rpy="0 0 0" xyz="0. 0. 0."/>
        <geometry>
            <box size="0.6 0.4 0.02"/>
        </geometry>
        <material name="panda white"/>
    </visual>

   <!-- Right-->
    <visual>
        <origin rpy="0 0 0" xyz="0. 0.2 0.1"/>
        <geometry>
            <box size="0.6 0.02 0.2"/>
        </geometry>
        <material name="panda white"/>
    </visual>

   <!-- Left-->
    <visual>
        <origin rpy="0 0 0" xyz="0. -0.2 0.1"/>
        <geometry>
            <box size="0.6 0.02 0.2"/>
        </geometry>
        <material name="panda white"/>
    </visual>

   <!-- Front-->
    <visual>
        <origin rpy="0 0 0" xyz="0.3 0. 0.1"/>
        <geometry>
            <box size="0.02 0.4 0.2"/>
        </geometry>
        <material name="green"/>
    </visual>

   <!-- Bottom-->
    <collision>
        <origin rpy="0 0 0" xyz="0. 0. 0."/>
        <geometry>
            <box size="0.6 0.4 0.02"/>
        </geometry>
        <material name="panda white"/>
    </collision>

   <!-- Right-->
    <collision>
        <origin rpy="0 0 0" xyz="0. 0.2 0.1"/>
        <geometry>
            <box size="0.6 0.02 0.2"/>
        </geometry>
        <material name="panda white"/>
    </collision>

   <!-- Left-->
    <collision>
        <origin rpy="0 0 0" xyz="0. -0.2 0.1"/>
        <geometry>
            <box size="0.6 0.02 0.2"/>
        </geometry>
        <material name="panda white"/>
    </collision>

   <!-- Front-->
    <collision>
        <origin rpy="0 0 0" xyz="0.3 0. 0.1"/>
        <geometry>
            <box size="0.02 0.4 0.2"/>
        </geometry>
        <material name="panda white"/>
    </collision>
  </link>

  <link name="drawer2">
  <!-- Bottom-->
    <visual>
        <origin rpy="0 0 0" xyz="0. 0. 0."/>
        <geometry>
            <box size="0.6 0.4 0.02"/>
        </geometry>
        <material name="panda white"/>
    </visual>

   <!-- Right-->
    <visual>
        <origin rpy="0 0 0" xyz="0. 0.2 0.1"/>
        <geometry>
            <box size="0.6 0.02 0.2"/>
        </geometry>
        <material name="panda white"/>
    </visual>

   <!-- Left-->
    <visual>
        <origin rpy="0 0 0" xyz="0. -0.2 0.1"/>
        <geometry>
            <box size="0.6 0.02 0.2"/>
        </geometry>
        <material name="panda white"/>
    </visual>

   <!-- Front-->
    <visual>
        <origin rpy="0 0 0" xyz="0.3 0. 0.1"/>
        <geometry>
            <box size="0.02 0.4 0.2"/>
        </geometry>
        <material name="green"/>
    </visual>

   <!-- Bottom-->
    <collision>
        <origin rpy="0 0 0" xyz="0. 0. 0."/>
        <geometry>
            <box size="0.6 0.4 0.02"/>
        </geometry>
        <material name="panda white"/>
    </collision>

   <!-- Right-->
    <collision>
        <origin rpy="0 0 0" xyz="0. 0.2 0.1"/>
        <geometry>
            <box size="0.6 0.02 0.2"/>
        </geometry>
        <material name="panda white"/>
    </collision>

   <!-- Left-->
    <collision>
        <origin rpy="0 0 0" xyz="0. -0.2 0.1"/>
        <geometry>
            <box size="0.6 0.02 0.2"/>
        </geometry>
        <material name="panda white"/>
    </collision>

   <!-- Front-->
    <collision>
        <origin rpy="0 0 0" xyz="0.3 0. 0.1"/>
        <geometry>
            <box size="0.02 0.4 0.2"/>
        </geometry>
        <material name="panda white"/>
    </collision>
  </link>

  <link name="drawer3">
  <!-- Bottom-->
    <visual>
        <origin rpy="0 0 0" xyz="0. 0. 0."/>
        <geometry>
            <box size="0.6 0.4 0.02"/>
        </geometry>
        <material name="panda white"/>
    </visual>

   <!-- Right-->
    <visual>
        <origin rpy="0 0 0" xyz="0. 0.2 0.1"/>
        <geometry>
            <box size="0.6 0.02 0.2"/>
        </geometry>
        <material name="panda white"/>
    </visual>

   <!-- Left-->
    <visual>
        <origin rpy="0 0 0" xyz="0. -0.2 0.1"/>
        <geometry>
            <box size="0.6 0.02 0.2"/>
        </geometry>
        <material name="panda white"/>
    </visual>

   <!-- Front-->
    <visual>
        <origin rpy="0 0 0" xyz="0.3 0. 0.1"/>
        <geometry>
            <box size="0.02 0.4 0.2"/>
        </geometry>
        <material name="green"/>
    </visual>

   <!-- Bottom-->
    <collision>
        <origin rpy="0 0 0" xyz="0. 0. 0."/>
        <geometry>
            <box size="0.6 0.4 0.02"/>
        </geometry>
        <material name="panda white"/>
    </collision>

   <!-- Right-->
    <collision>
        <origin rpy="0 0 0" xyz="0. 0.2 0.1"/>
        <geometry>
            <box size="0.6 0.02 0.2"/>
        </geometry>
        <material name="panda white"/>
    </collision>

   <!-- Left-->
    <collision>
        <origin rpy="0 0 0" xyz="0. -0.2 0.1"/>
        <geometry>
            <box size="0.6 0.02 0.2"/>
        </geometry>
        <material name="panda white"/>
    </collision>

   <!-- Front-->
    <collision>
        <origin rpy="0 0 0" xyz="0.3 0. 0.1"/>
        <geometry>
            <box size="0.02 0.4 0.2"/>
        </geometry>
        <material name="panda white"/>
    </collision>
  </link>


  <link name="drawer4">
  <!-- Bottom-->
    <visual>
        <origin rpy="0 0 0" xyz="0. 0. 0."/>
        <geometry>
            <box size="0.6 0.4 0.02"/>
        </geometry>
        <material name="panda white"/>
    </visual>

   <!-- Right-->
    <visual>
        <origin rpy="0 0 0" xyz="0. 0.2 0.1"/>
        <geometry>
            <box size="0.6 0.02 0.2"/>
        </geometry>
        <material name="panda white"/>
    </visual>

   <!-- Left-->
    <visual>
        <origin rpy="0 0 0" xyz="0. -0.2 0.1"/>
        <geometry>
            <box size="0.6 0.02 0.2"/>
        </geometry>
        <material name="panda white"/>
    </visual>

   <!-- Front-->
    <visual>
        <origin rpy="0 0 0" xyz="0.3 0. 0.1"/>
        <geometry>
            <box size="0.02 0.4 0.2"/>
        </geometry>
        <material name="green"/>
    </visual>

   <!-- Bottom-->
    <collision>
        <origin rpy="0 0 0" xyz="0. 0. 0."/>
        <geometry>
            <box size="0.6 0.4 0.02"/>
        </geometry>
        <material name="panda white"/>
    </collision>

   <!-- Right-->
    <collision>
        <origin rpy="0 0 0" xyz="0. 0.2 0.1"/>
        <geometry>
            <box size="0.6 0.02 0.2"/>
        </geometry>
        <material name="panda white"/>
    </collision>

   <!-- Left-->
    <collision>
        <origin rpy="0 0 0" xyz="0. -0.2 0.1"/>
        <geometry>
            <box size="0.6 0.02 0.2"/>
        </geometry>
        <material name="panda white"/>
    </collision>

   <!-- Front-->
    <collision>
        <origin rpy="0 0 0" xyz="0.3 0. 0.1"/>
        <geometry>
            <box size="0.02 0.4 0.2"/>
        </geometry>
        <material name="panda white"/>
    </collision>
  </link>


 <joint name="door1_joint" type="revolute">
    <origin rpy="0 0 0" xyz="0.3 0.1 .4"/>
    <parent link="table_base"/>
    <child link="door1"/>
    <axis xyz="0 0 1"/>
    <limit effort="12" lower="-2.8973" upper="2.8973" velocity="2.6100"/>
    <safety_controller k_position="100.0" k_velocity="40.0" soft_lower_limit="-2.8973" soft_upper_limit="2.8973"/>
  </joint>

 <joint name="door2_joint" type="revolute">
    <origin rpy="0 0 0" xyz="0.3 0.9 .4"/>
    <parent link="table_base"/>
    <child link="door2"/>
    <axis xyz="0 0 1"/>
    <limit effort="12" lower="-2.8973" upper="2.8973" velocity="2.6100"/>
    <safety_controller k_position="100.0" k_velocity="40.0" soft_lower_limit="-2.8973" soft_upper_limit="2.8973"/>
  </joint>

  <joint name="door3_joint" type="revolute">
    <origin rpy="0 0 0" xyz="0.3 -0.9 .4"/>
    <parent link="table_base"/>
    <child link="door3"/>
    <axis xyz="0 0 1"/>
    <limit effort="12" lower="-2.8973" upper="2.8973" velocity="2.6100"/>
    <safety_controller k_position="100.0" k_velocity="40.0" soft_lower_limit="-2.8973" soft_upper_limit="2.8973"/>
  </joint>

   <joint name="door4_joint" type="revolute">
    <origin rpy="0 0 0" xyz="0.3 -0.5 .4"/>
    <parent link="table_base"/>
    <child link="door4"/>
    <axis xyz="0 0 1"/>
    <limit effort="12" lower="-2.8973" upper="2.8973" velocity="2.6100"/>
    <safety_controller k_position="100.0" k_velocity="40.0" soft_lower_limit="-2.8973" soft_upper_limit="2.8973"/>
  </joint>


  <joint name="drawer1_joint" type="prismatic">
    <origin rpy="0 0 0" xyz="0. -0.1 ."/>
    <parent link="table_base"/>
    <child link="drawer1"/>
    <axis xyz="1 0 0"/>
    <limit effort="12" lower="-2.8973" upper="2.8973" velocity="2.6100"/>
    <safety_controller k_position="100.0" k_velocity="40.0" soft_lower_limit="-2.8973" soft_upper_limit="2.8973"/>
  </joint>

  <joint name="drawer2_joint" type="prismatic">
    <origin rpy="0 0 0" xyz="0. -0.1 .2"/>
    <parent link="table_base"/>
    <child link="drawer2"/>
    <axis xyz="1 0 0"/>
    <limit effort="12" lower="-2.8973" upper="2.8973" velocity="2.6100"/>
    <safety_controller k_position="100.0" k_velocity="40.0" soft_lower_limit="-2.8973" soft_upper_limit="2.8973"/>
  </joint>

  <joint name="drawer3_joint" type="prismatic">
    <origin rpy="0 0 0" xyz="0. -0.1 .4"/>
    <parent link="table_base"/>
    <child link="drawer3"/>
    <axis xyz="1 0 0"/>
    <limit effort="12" lower="-2.8973" upper="2.8973" velocity="2.6100"/>
    <safety_controller k_position="100.0" k_velocity="40.0" soft_lower_limit="-2.8973" soft_upper_limit="2.8973"/>
  </joint>

  <joint name="drawer4_joint" type="prismatic">
    <origin rpy="0 0 0" xyz="0. -0.1 .6"/>
    <parent link="table_base"/>
    <child link="drawer4"/>
    <axis xyz="1 0 0"/>
    <limit effort="12" lower="-2.8973" upper="2.8973" velocity="2.6100"/>
    <safety_controller k_position="100.0" k_velocity="40.0" soft_lower_limit="-2.8973" soft_upper_limit="2.8973"/>
  </joint>


  <!-- MATERIALS -->
  <material name="panda_white">
    <color rgba="1. 1. 1. 1."/>
  </material>
  <material name="aluminium">
    <color rgba="0.5 0.5 0.5 1"/>
  </material>
  <material name="red">
    <color rgba=".8 0.3 0.3 1."/>
  </material>
  <material name="green">
    <color rgba="0 1 0 .7"/>
  </material>
</robot>

